<?xml version="1.0" ?>
<robot name="seto_scararobot">

    <link name="world"/>

    <link name="base_link">
        <visual>
            <geometry>
                <mesh filename="package://seto_scararobot2_description/meshes/base.stl" />
            </geometry>
            <material name="gray">
                <color rgba="0.5 0.5 0.5 2.0" />
            </material>
        </visual>
        <collision>
            <geometry>
                <mesh filename="package://seto_scararobot2_description/meshes/base.stl" />
            </geometry>
            <origin xyz="0 0 0" rpy="0 0 0"/>
        </collision>
        <inertial>
            <origin xyz="0.00003 -0.00017 0.066228" rpy="0 0 0"/>       <!-- Center of gravity (m) -->
            <mass value="2.935"/>                                       <!-- mass (kg) -->
            <inertia ixx="725.3" ixy="0.002201" ixz="-0.01514"
                    iyy="518.7" iyz="0.9947"
                    izz="868.9"/>                                       <!-- inertia (kg.m^2) -->
        </inertial>
    </link>

    <link name="arm1_link">
        <visual>
            <geometry>
                <mesh filename="package://seto_scararobot2_description/meshes/arm1.stl" />
            </geometry>
            <material name="green">
                <color rgba="0.0 1.0 0. 2.0" />
            </material>
        </visual>
        <collision>
            <geometry>
                <mesh filename="package://seto_scararobot2_description/meshes/arm1.stl" />
            </geometry>
            <origin xyz="0 0 0" rpy="0 0 0"/>
        </collision>
        <inertial>
            <origin xyz="0 0.0451 -0.004" rpy="0 0 0"/>                 <!-- Center of gravity (m) -->
            <mass value="0.042"/>                                       <!-- mass (kg) -->
            <inertia ixx="0.621" ixy="0" ixz="0"
                    iyy="0.07151" iyz="0.002973"
                    izz="0.688"/>                                       <!-- inertia (kg.m^2) -->
        </inertial>
    </link>

    <link name="arm2_link">
        <visual>
            <geometry>
                <mesh filename="package://seto_scararobot2_description/meshes/arm2.stl" />
            </geometry>
            <material name="red">
                <color rgba="1.0 0.0 0.0 2.0" />
            </material>
        </visual>
        <collision>
            <geometry>
                <mesh filename="package://seto_scararobot2_description/meshes/arm2.stl" />
            </geometry>
            <origin xyz="0 0 0" rpy="0 0 0"/>
        </collision>
        <inertial>
            <origin xyz="-0.004448 -0.025191 -0.056949" rpy="0 0 0"/>   <!-- Center of gravity (m) -->
            <mass value="0.221"/>                                       <!-- mass (kg) -->
            <inertia ixx="10.39" ixy="-0.3337" ixz="-0.3772"
                    iyy="5.693" iyz="-3.025"
                    izz="5.866"/>                                       <!-- inertia (kg.m^2) -->
        </inertial>
    </link>
    
    <link name="endpoint"> <!-- Control POINT !!!!!! -->
        <inertial>
            <origin xyz="0 0 0" rpy="0 0 0" />            <!-- Center of gravity (m) -->
            <mass value = "0.001" />                      <!-- mass (kg) -->
            <inertia ixx = "1.0" ixy = "0.0" ixz = "0.0" iyy =" 1.0" iyz =" 0.0" izz =" 1.0"/><!-- inertia (kg.m^2) -->
        </inertial>
    </link>

    <joint name="fixed_world" type="fixed">
        <parent link="world"/>
        <child link="base_link"/>
        <origin xyz="0 0 0.01" rpy="0 0 0" />
    </joint>
    <joint name="base_to_arm1" type="revolute">
        <parent link="base_link" />
        <child link="arm1_link" />
        <origin xyz="0 0 0.10200" rpy="0 0 0" />
        <axis xyz="0 0 -1" />
        <limit effort="1000.0" lower="-1.57079633" upper="1.57079633" velocity="2.0" />
    </joint>
    <joint name="arm1_to_arm2" type="revolute">
        <parent link="arm1_link" />
        <child link="arm2_link" />
        <origin xyz="0.09025 0 0" rpy="0 0 0" />
        <axis xyz="0 0 -1" />
        <limit effort="1000.0" lower="-3.14159" upper="3.14159" velocity="2.0" />
    </joint>
    <joint name="end_joint" type="revolute">
        <parent link="arm2_link" />
        <child link="endpoint" />
        <origin xyz="0.09025 0 0" rpy="0 0 0" />
        <axis xyz="0 0 1" />
        <limit effort="1000.0" lower="-3.14159" upper="3.14159" velocity="2.0" />
    </joint>

    <transmission name="trans_base_to_arm1">
        <type>transmission_interface/SimpleTransmission</type>
        <joint name="base_to_arm1">
            <hardwareInterface>hardware_interface/PositionJointInterface</hardwareInterface>
        </joint>
        <actuator name="base_to_arm1_motor">
            <hardwareInterface>hardware_interface/PositionJointInterface</hardwareInterface>
            <mechanicalReduction>1</mechanicalReduction>
        </actuator>
    </transmission>
    <transmission name="trans_arm1_to_arm2">
        <type>transmission_interface/SimpleTransmission</type>
        <joint name="arm1_to_arm2">
            <hardwareInterface>hardware_interface/PositionJointInterface</hardwareInterface>
        </joint>
        <actuator name="arm1_to_arm2_motor">
            <hardwareInterface>hardware_interface/PositionJointInterface</hardwareInterface>
            <mechanicalReduction>1</mechanicalReduction>
        </actuator>
    </transmission>
    <transmission name="trans_end_joint">
        <type>transmission_interface/SimpleTransmission</type>
        <joint name="end_joint">
            <hardwareInterface>hardware_interface/PositionJointInterface</hardwareInterface>
        </joint>
        <actuator name="end_joint_motor">
            <hardwareInterface>hardware_interface/PositionJointInterface</hardwareInterface>
            <mechanicalReduction>1</mechanicalReduction>
        </actuator>
    </transmission>
    <gazebo>
        <plugin name="gazebo_ros_control" filename="libgazebo_ros_control.so">
            <robotNamespace>/</robotNamespace>
        </plugin>
    </gazebo>
</robot>
